2022-03-14 23:03:09,776 ERROR: Exception on /auth/login [GET] [in /home/kenneth/myrenamer/venv/lib/python3.8/site-packages/flask/app.py:1457]
Traceback (most recent call last):
  File "/home/kenneth/myrenamer/venv/lib/python3.8/site-packages/flask/app.py", line 2073, in wsgi_app
    response = self.full_dispatch_request()
  File "/home/kenneth/myrenamer/venv/lib/python3.8/site-packages/flask/app.py", line 1518, in full_dispatch_request
    rv = self.handle_user_exception(e)
  File "/home/kenneth/myrenamer/venv/lib/python3.8/site-packages/flask/app.py", line 1516, in full_dispatch_request
    rv = self.dispatch_request()
  File "/home/kenneth/myrenamer/venv/lib/python3.8/site-packages/flask/app.py", line 1502, in dispatch_request
    return self.ensure_sync(self.view_functions[rule.endpoint])(**req.view_args)
  File "/home/kenneth/myrenamer/app/auth/routes.py", line 26, in login
    return render_template('login.html', title=_('Sign In'), form=form)
  File "/home/kenneth/myrenamer/venv/lib/python3.8/site-packages/flask/templating.py", line 148, in render_template
    ctx.app.jinja_env.get_or_select_template(template_name_or_list),
  File "/home/kenneth/myrenamer/venv/lib/python3.8/site-packages/jinja2/environment.py", line 1068, in get_or_select_template
    return self.get_template(template_name_or_list, parent, globals)
  File "/home/kenneth/myrenamer/venv/lib/python3.8/site-packages/jinja2/environment.py", line 997, in get_template
    return self._load_template(name, globals)
  File "/home/kenneth/myrenamer/venv/lib/python3.8/site-packages/jinja2/environment.py", line 958, in _load_template
    template = self.loader.load(self, name, self.make_globals(globals))
  File "/home/kenneth/myrenamer/venv/lib/python3.8/site-packages/jinja2/loaders.py", line 125, in load
    source, filename, uptodate = self.get_source(environment, name)
  File "/home/kenneth/myrenamer/venv/lib/python3.8/site-packages/flask/templating.py", line 59, in get_source
    return self._get_source_fast(environment, template)
  File "/home/kenneth/myrenamer/venv/lib/python3.8/site-packages/flask/templating.py", line 95, in _get_source_fast
    raise TemplateNotFound(template)
jinja2.exceptions.TemplateNotFound: login.html
2022-03-14 23:05:33,579 INFO: My Renamer Startup [in /home/kenneth/myrenamer/app/__init__.py:74]
2022-03-15 03:14:31,934 INFO: My Renamer Startup [in /home/kenneth/myrenamer/app/__init__.py:74]
2022-03-15 03:16:48,260 INFO: My Renamer Startup [in /home/kenneth/myrenamer/app/__init__.py:74]
2022-03-15 03:20:10,285 INFO: My Renamer Startup [in /home/kenneth/myrenamer/app/__init__.py:74]
2022-03-15 03:27:15,663 INFO: My Renamer Startup [in /home/kenneth/myrenamer/app/__init__.py:74]
2022-03-15 06:26:53,921 INFO: My Renamer Startup [in /home/kenneth/myrenamer/app/__init__.py:78]
2022-03-15 07:27:33,574 INFO: My Renamer Startup [in /home/kenneth/myrenamer/app/__init__.py:78]
2022-03-15 07:32:07,699 INFO: My Renamer Startup [in /home/kenneth/myrenamer/app/__init__.py:78]
2022-03-16 05:52:05,942 INFO: My Renamer Startup [in /home/kenneth/myrenamer/app/__init__.py:78]
2022-03-16 05:52:19,457 ERROR: Exception on / [GET] [in /home/kenneth/myrenamer/venv/lib/python3.8/site-packages/flask/app.py:1457]
Traceback (most recent call last):
  File "/home/kenneth/myrenamer/venv/lib/python3.8/site-packages/flask/app.py", line 2073, in wsgi_app
    response = self.full_dispatch_request()
  File "/home/kenneth/myrenamer/venv/lib/python3.8/site-packages/flask/app.py", line 1518, in full_dispatch_request
    rv = self.handle_user_exception(e)
  File "/home/kenneth/myrenamer/venv/lib/python3.8/site-packages/flask/app.py", line 1514, in full_dispatch_request
    rv = self.preprocess_request()
  File "/home/kenneth/myrenamer/venv/lib/python3.8/site-packages/flask/app.py", line 1857, in preprocess_request
    rv = self.ensure_sync(before_func)()
  File "/home/kenneth/myrenamer/app/main/routes.py", line 61, in before_request
    db.session.commit()
  File "<string>", line 2, in commit
  File "/home/kenneth/myrenamer/venv/lib/python3.8/site-packages/sqlalchemy/orm/session.py", line 1431, in commit
    self._transaction.commit(_to_root=self.future)
  File "/home/kenneth/myrenamer/venv/lib/python3.8/site-packages/sqlalchemy/orm/session.py", line 829, in commit
    self._prepare_impl()
  File "/home/kenneth/myrenamer/venv/lib/python3.8/site-packages/sqlalchemy/orm/session.py", line 797, in _prepare_impl
    self.session.dispatch.before_commit(self.session)
  File "/home/kenneth/myrenamer/venv/lib/python3.8/site-packages/sqlalchemy/event/attr.py", line 256, in __call__
    fn(*args, **kw)
  File "/home/kenneth/myrenamer/app/models.py", line 111, in before_commit
    'delete': list(session.delete)
TypeError: 'method' object is not iterable
2022-03-16 05:54:20,957 INFO: My Renamer Startup [in /home/kenneth/myrenamer/app/__init__.py:78]
2022-03-16 05:54:22,644 ERROR: Exception on / [GET] [in /home/kenneth/myrenamer/venv/lib/python3.8/site-packages/flask/app.py:1457]
Traceback (most recent call last):
  File "/home/kenneth/myrenamer/venv/lib/python3.8/site-packages/flask/app.py", line 2073, in wsgi_app
    response = self.full_dispatch_request()
  File "/home/kenneth/myrenamer/venv/lib/python3.8/site-packages/flask/app.py", line 1518, in full_dispatch_request
    rv = self.handle_user_exception(e)
  File "/home/kenneth/myrenamer/venv/lib/python3.8/site-packages/flask/app.py", line 1514, in full_dispatch_request
    rv = self.preprocess_request()
  File "/home/kenneth/myrenamer/venv/lib/python3.8/site-packages/flask/app.py", line 1857, in preprocess_request
    rv = self.ensure_sync(before_func)()
  File "/home/kenneth/myrenamer/app/main/routes.py", line 61, in before_request
    db.session.commit()
  File "<string>", line 2, in commit
  File "/home/kenneth/myrenamer/venv/lib/python3.8/site-packages/sqlalchemy/orm/session.py", line 1431, in commit
    self._transaction.commit(_to_root=self.future)
  File "/home/kenneth/myrenamer/venv/lib/python3.8/site-packages/sqlalchemy/orm/session.py", line 829, in commit
    self._prepare_impl()
  File "/home/kenneth/myrenamer/venv/lib/python3.8/site-packages/sqlalchemy/orm/session.py", line 797, in _prepare_impl
    self.session.dispatch.before_commit(self.session)
  File "/home/kenneth/myrenamer/venv/lib/python3.8/site-packages/sqlalchemy/event/attr.py", line 256, in __call__
    fn(*args, **kw)
  File "/home/kenneth/myrenamer/app/models.py", line 111, in before_commit
    'delete': list(session.delete)
TypeError: 'method' object is not iterable
2022-03-16 05:55:28,166 INFO: My Renamer Startup [in /home/kenneth/myrenamer/app/__init__.py:78]
2022-03-16 05:55:29,654 ERROR: Exception on / [GET] [in /home/kenneth/myrenamer/venv/lib/python3.8/site-packages/flask/app.py:1457]
Traceback (most recent call last):
  File "/home/kenneth/myrenamer/venv/lib/python3.8/site-packages/flask/app.py", line 2073, in wsgi_app
    response = self.full_dispatch_request()
  File "/home/kenneth/myrenamer/venv/lib/python3.8/site-packages/flask/app.py", line 1518, in full_dispatch_request
    rv = self.handle_user_exception(e)
  File "/home/kenneth/myrenamer/venv/lib/python3.8/site-packages/flask/app.py", line 1514, in full_dispatch_request
    rv = self.preprocess_request()
  File "/home/kenneth/myrenamer/venv/lib/python3.8/site-packages/flask/app.py", line 1857, in preprocess_request
    rv = self.ensure_sync(before_func)()
  File "/home/kenneth/myrenamer/app/main/routes.py", line 61, in before_request
    db.session.commit()
  File "<string>", line 2, in commit
  File "/home/kenneth/myrenamer/venv/lib/python3.8/site-packages/sqlalchemy/orm/session.py", line 1431, in commit
    self._transaction.commit(_to_root=self.future)
  File "/home/kenneth/myrenamer/venv/lib/python3.8/site-packages/sqlalchemy/orm/session.py", line 829, in commit
    self._prepare_impl()
  File "/home/kenneth/myrenamer/venv/lib/python3.8/site-packages/sqlalchemy/orm/session.py", line 797, in _prepare_impl
    self.session.dispatch.before_commit(self.session)
  File "/home/kenneth/myrenamer/venv/lib/python3.8/site-packages/sqlalchemy/event/attr.py", line 256, in __call__
    fn(*args, **kw)
  File "/home/kenneth/myrenamer/app/models.py", line 100, in before_commit
    'delete': list(session.delete)
TypeError: 'method' object is not iterable
2022-03-16 05:58:56,710 INFO: My Renamer Startup [in /home/kenneth/myrenamer/app/__init__.py:78]
2022-03-16 05:59:11,490 ERROR: Exception on /search [GET] [in /home/kenneth/myrenamer/venv/lib/python3.8/site-packages/flask/app.py:1457]
Traceback (most recent call last):
  File "/home/kenneth/myrenamer/venv/lib/python3.8/site-packages/flask/app.py", line 2073, in wsgi_app
    response = self.full_dispatch_request()
  File "/home/kenneth/myrenamer/venv/lib/python3.8/site-packages/flask/app.py", line 1518, in full_dispatch_request
    rv = self.handle_user_exception(e)
  File "/home/kenneth/myrenamer/venv/lib/python3.8/site-packages/flask/app.py", line 1516, in full_dispatch_request
    rv = self.dispatch_request()
  File "/home/kenneth/myrenamer/venv/lib/python3.8/site-packages/flask/app.py", line 1502, in dispatch_request
    return self.ensure_sync(self.view_functions[rule.endpoint])(**req.view_args)
  File "/home/kenneth/myrenamer/venv/lib/python3.8/site-packages/flask_login/utils.py", line 272, in decorated_view
    return func(*args, **kwargs)
  File "/home/kenneth/myrenamer/app/main/routes.py", line 145, in search
    if not g.search_form_validate():
  File "/home/kenneth/myrenamer/venv/lib/python3.8/site-packages/flask/ctx.py", line 51, in __getattr__
    raise AttributeError(name) from None
AttributeError: search_form_validate
2022-03-16 06:00:45,022 INFO: My Renamer Startup [in /home/kenneth/myrenamer/app/__init__.py:78]
