2022-02-27 16:54:22,345 ERROR: Exception on /favicon.ico [GET] [in /home/kenneth/myrenamer/venv/lib/python3.8/site-packages/flask/app.py:1457
Traceback (most recent call last):
  File "/home/kenneth/myrenamer/venv/lib/python3.8/site-packages/flask/app.py", line 1516, in full_dispatch_request
    rv = self.dispatch_request()
  File "/home/kenneth/myrenamer/venv/lib/python3.8/site-packages/flask/app.py", line 1492, in dispatch_request
    self.raise_routing_exception(req)
  File "/home/kenneth/myrenamer/venv/lib/python3.8/site-packages/flask/app.py", line 1474, in raise_routing_exception
    raise request.routing_exception  # type: ignore
  File "/home/kenneth/myrenamer/venv/lib/python3.8/site-packages/flask/ctx.py", line 376, in match_request
    result = self.url_adapter.match(return_rule=True)  # type: ignore
  File "/home/kenneth/myrenamer/venv/lib/python3.8/site-packages/werkzeug/routing.py", line 2042, in match
    raise NotFound()
werkzeug.exceptions.NotFound: 404 Not Found: The requested URL was not found on the server. If you entered the URL manually please check your spelling and try again.

During handling of the above exception, another exception occurred:

Traceback (most recent call last):
  File "/home/kenneth/myrenamer/venv/lib/python3.8/site-packages/flask/app.py", line 2073, in wsgi_app
    response = self.full_dispatch_request()
  File "/home/kenneth/myrenamer/venv/lib/python3.8/site-packages/flask/app.py", line 1518, in full_dispatch_request
    rv = self.handle_user_exception(e)
  File "/home/kenneth/myrenamer/venv/lib/python3.8/site-packages/flask/app.py", line 1386, in handle_user_exception
    return self.handle_http_exception(e)
  File "/home/kenneth/myrenamer/venv/lib/python3.8/site-packages/flask/app.py", line 1326, in handle_http_exception
    return self.ensure_sync(handler)(e)
  File "/home/kenneth/myrenamer/app/errors.py", line 6, in not_found_error
    return render_template('404.html'), 404
  File "/home/kenneth/myrenamer/venv/lib/python3.8/site-packages/flask/templating.py", line 147, in render_template
    return _render(
  File "/home/kenneth/myrenamer/venv/lib/python3.8/site-packages/flask/templating.py", line 128, in _render
    rv = template.render(context)
  File "/home/kenneth/myrenamer/venv/lib/python3.8/site-packages/jinja2/environment.py", line 1291, in render
    self.environment.handle_exception()
  File "/home/kenneth/myrenamer/venv/lib/python3.8/site-packages/jinja2/environment.py", line 925, in handle_exception
    raise rewrite_traceback_stack(source=source)
  File "/home/kenneth/myrenamer/app/templates/404.html", line 1, in top-level template code
    {% extends "base.html" %}
  File "/home/kenneth/myrenamer/venv/lib/python3.8/site-packages/jinja2/environment.py", line 925, in handle_exception
    raise rewrite_traceback_stack(source=source)
  File "/home/kenneth/myrenamer/app/templates/base.html", line 50, in template
    {% endblock %)
jinja2.exceptions.TemplateSyntaxError: expected token 'end of statement block', got '%'
2022-02-27 16:54:30,275 INFO: My Renamer startup [in /home/kenneth/myrenamer/app/__init__.py:48
2022-02-27 16:54:32,236 ERROR: Exception on /login [GET] [in /home/kenneth/myrenamer/venv/lib/python3.8/site-packages/flask/app.py:1457
Traceback (most recent call last):
  File "/home/kenneth/myrenamer/venv/lib/python3.8/site-packages/flask/app.py", line 2073, in wsgi_app
    response = self.full_dispatch_request()
  File "/home/kenneth/myrenamer/venv/lib/python3.8/site-packages/flask/app.py", line 1518, in full_dispatch_request
    rv = self.handle_user_exception(e)
  File "/home/kenneth/myrenamer/venv/lib/python3.8/site-packages/flask/app.py", line 1516, in full_dispatch_request
    rv = self.dispatch_request()
  File "/home/kenneth/myrenamer/venv/lib/python3.8/site-packages/flask/app.py", line 1502, in dispatch_request
    return self.ensure_sync(self.view_functions[rule.endpoint])(**req.view_args)
  File "/home/kenneth/myrenamer/app/routes.py", line 50, in login
    return render_template('login.html', title='Sign In', form=form)
  File "/home/kenneth/myrenamer/venv/lib/python3.8/site-packages/flask/templating.py", line 147, in render_template
    return _render(
  File "/home/kenneth/myrenamer/venv/lib/python3.8/site-packages/flask/templating.py", line 128, in _render
    rv = template.render(context)
  File "/home/kenneth/myrenamer/venv/lib/python3.8/site-packages/jinja2/environment.py", line 1291, in render
    self.environment.handle_exception()
  File "/home/kenneth/myrenamer/venv/lib/python3.8/site-packages/jinja2/environment.py", line 925, in handle_exception
    raise rewrite_traceback_stack(source=source)
  File "/home/kenneth/myrenamer/app/templates/login.html", line 1, in top-level template code
    {% extends "base.html" %}
  File "/home/kenneth/myrenamer/venv/lib/python3.8/site-packages/jinja2/environment.py", line 925, in handle_exception
    raise rewrite_traceback_stack(source=source)
  File "/home/kenneth/myrenamer/app/templates/base.html", line 50, in template
    {% endblock %)
jinja2.exceptions.TemplateSyntaxError: expected token 'end of statement block', got '%'
2022-02-27 16:54:33,493 ERROR: Exception on /favicon.ico [GET] [in /home/kenneth/myrenamer/venv/lib/python3.8/site-packages/flask/app.py:1457
Traceback (most recent call last):
  File "/home/kenneth/myrenamer/venv/lib/python3.8/site-packages/flask/app.py", line 1516, in full_dispatch_request
    rv = self.dispatch_request()
  File "/home/kenneth/myrenamer/venv/lib/python3.8/site-packages/flask/app.py", line 1492, in dispatch_request
    self.raise_routing_exception(req)
  File "/home/kenneth/myrenamer/venv/lib/python3.8/site-packages/flask/app.py", line 1474, in raise_routing_exception
    raise request.routing_exception  # type: ignore
  File "/home/kenneth/myrenamer/venv/lib/python3.8/site-packages/flask/ctx.py", line 376, in match_request
    result = self.url_adapter.match(return_rule=True)  # type: ignore
  File "/home/kenneth/myrenamer/venv/lib/python3.8/site-packages/werkzeug/routing.py", line 2042, in match
    raise NotFound()
werkzeug.exceptions.NotFound: 404 Not Found: The requested URL was not found on the server. If you entered the URL manually please check your spelling and try again.

During handling of the above exception, another exception occurred:

Traceback (most recent call last):
  File "/home/kenneth/myrenamer/venv/lib/python3.8/site-packages/flask/app.py", line 2073, in wsgi_app
    response = self.full_dispatch_request()
  File "/home/kenneth/myrenamer/venv/lib/python3.8/site-packages/flask/app.py", line 1518, in full_dispatch_request
    rv = self.handle_user_exception(e)
  File "/home/kenneth/myrenamer/venv/lib/python3.8/site-packages/flask/app.py", line 1386, in handle_user_exception
    return self.handle_http_exception(e)
  File "/home/kenneth/myrenamer/venv/lib/python3.8/site-packages/flask/app.py", line 1326, in handle_http_exception
    return self.ensure_sync(handler)(e)
  File "/home/kenneth/myrenamer/app/errors.py", line 6, in not_found_error
    return render_template('404.html'), 404
  File "/home/kenneth/myrenamer/venv/lib/python3.8/site-packages/flask/templating.py", line 147, in render_template
    return _render(
  File "/home/kenneth/myrenamer/venv/lib/python3.8/site-packages/flask/templating.py", line 128, in _render
    rv = template.render(context)
  File "/home/kenneth/myrenamer/venv/lib/python3.8/site-packages/jinja2/environment.py", line 1291, in render
    self.environment.handle_exception()
  File "/home/kenneth/myrenamer/venv/lib/python3.8/site-packages/jinja2/environment.py", line 925, in handle_exception
    raise rewrite_traceback_stack(source=source)
  File "/home/kenneth/myrenamer/app/templates/404.html", line 1, in top-level template code
    {% extends "base.html" %}
  File "/home/kenneth/myrenamer/venv/lib/python3.8/site-packages/jinja2/environment.py", line 925, in handle_exception
    raise rewrite_traceback_stack(source=source)
  File "/home/kenneth/myrenamer/app/templates/base.html", line 50, in template
    {% endblock %)
jinja2.exceptions.TemplateSyntaxError: expected token 'end of statement block', got '%'
2022-02-27 17:02:41,681 INFO: My Renamer startup [in /home/kenneth/myrenamer/app/__init__.py:48
2022-02-27 17:03:20,217 INFO: My Renamer startup [in /home/kenneth/myrenamer/app/__init__.py:48
2022-02-27 17:24:52,999 INFO: My Renamer startup [in /home/kenneth/myrenamer/app/__init__.py:48
2022-02-27 18:13:21,669 INFO: My Renamer startup [in /home/kenneth/myrenamer/app/__init__.py:50
