2022-03-19 01:21:42,995 ERROR: Exception on /favicon.ico [GET] [in /home/kenneth/myrenamer/venv/lib/python3.8/site-packages/flask/app.py:1457]
Traceback (most recent call last):
  File "/home/kenneth/myrenamer/venv/lib/python3.8/site-packages/flask/app.py", line 1516, in full_dispatch_request
    rv = self.dispatch_request()
  File "/home/kenneth/myrenamer/venv/lib/python3.8/site-packages/flask/app.py", line 1492, in dispatch_request
    self.raise_routing_exception(req)
  File "/home/kenneth/myrenamer/venv/lib/python3.8/site-packages/flask/app.py", line 1474, in raise_routing_exception
    raise request.routing_exception  # type: ignore
  File "/home/kenneth/myrenamer/venv/lib/python3.8/site-packages/flask/ctx.py", line 376, in match_request
    result = self.url_adapter.match(return_rule=True)  # type: ignore
  File "/home/kenneth/myrenamer/venv/lib/python3.8/site-packages/werkzeug/routing.py", line 2042, in match
    raise NotFound()
werkzeug.exceptions.NotFound: 404 Not Found: The requested URL was not found on the server. If you entered the URL manually please check your spelling and try again.

During handling of the above exception, another exception occurred:

Traceback (most recent call last):
  File "/home/kenneth/myrenamer/venv/lib/python3.8/site-packages/flask/app.py", line 2073, in wsgi_app
    response = self.full_dispatch_request()
  File "/home/kenneth/myrenamer/venv/lib/python3.8/site-packages/flask/app.py", line 1518, in full_dispatch_request
    rv = self.handle_user_exception(e)
  File "/home/kenneth/myrenamer/venv/lib/python3.8/site-packages/flask/app.py", line 1386, in handle_user_exception
    return self.handle_http_exception(e)
  File "/home/kenneth/myrenamer/venv/lib/python3.8/site-packages/flask/app.py", line 1326, in handle_http_exception
    return self.ensure_sync(handler)(e)
  File "/home/kenneth/myrenamer/app/errors/handlers.py", line 7, in not_found_error
    return render_template('errors/404.html', 404)
TypeError: render_template() takes 1 positional argument but 2 were given
2022-03-19 01:22:11,390 ERROR: Exception on /favicon.ico [GET] [in /home/kenneth/myrenamer/venv/lib/python3.8/site-packages/flask/app.py:1457]
Traceback (most recent call last):
  File "/home/kenneth/myrenamer/venv/lib/python3.8/site-packages/flask/app.py", line 1516, in full_dispatch_request
    rv = self.dispatch_request()
  File "/home/kenneth/myrenamer/venv/lib/python3.8/site-packages/flask/app.py", line 1492, in dispatch_request
    self.raise_routing_exception(req)
  File "/home/kenneth/myrenamer/venv/lib/python3.8/site-packages/flask/app.py", line 1474, in raise_routing_exception
    raise request.routing_exception  # type: ignore
  File "/home/kenneth/myrenamer/venv/lib/python3.8/site-packages/flask/ctx.py", line 376, in match_request
    result = self.url_adapter.match(return_rule=True)  # type: ignore
  File "/home/kenneth/myrenamer/venv/lib/python3.8/site-packages/werkzeug/routing.py", line 2042, in match
    raise NotFound()
werkzeug.exceptions.NotFound: 404 Not Found: The requested URL was not found on the server. If you entered the URL manually please check your spelling and try again.

During handling of the above exception, another exception occurred:

Traceback (most recent call last):
  File "/home/kenneth/myrenamer/venv/lib/python3.8/site-packages/flask/app.py", line 2073, in wsgi_app
    response = self.full_dispatch_request()
  File "/home/kenneth/myrenamer/venv/lib/python3.8/site-packages/flask/app.py", line 1518, in full_dispatch_request
    rv = self.handle_user_exception(e)
  File "/home/kenneth/myrenamer/venv/lib/python3.8/site-packages/flask/app.py", line 1386, in handle_user_exception
    return self.handle_http_exception(e)
  File "/home/kenneth/myrenamer/venv/lib/python3.8/site-packages/flask/app.py", line 1326, in handle_http_exception
    return self.ensure_sync(handler)(e)
  File "/home/kenneth/myrenamer/app/errors/handlers.py", line 7, in not_found_error
    return render_template('errors/404.html', 404)
TypeError: render_template() takes 1 positional argument but 2 were given
2022-03-19 01:22:11,703 ERROR: Exception on /favicon.ico [GET] [in /home/kenneth/myrenamer/venv/lib/python3.8/site-packages/flask/app.py:1457]
Traceback (most recent call last):
  File "/home/kenneth/myrenamer/venv/lib/python3.8/site-packages/flask/app.py", line 1516, in full_dispatch_request
    rv = self.dispatch_request()
  File "/home/kenneth/myrenamer/venv/lib/python3.8/site-packages/flask/app.py", line 1492, in dispatch_request
    self.raise_routing_exception(req)
  File "/home/kenneth/myrenamer/venv/lib/python3.8/site-packages/flask/app.py", line 1474, in raise_routing_exception
    raise request.routing_exception  # type: ignore
  File "/home/kenneth/myrenamer/venv/lib/python3.8/site-packages/flask/ctx.py", line 376, in match_request
    result = self.url_adapter.match(return_rule=True)  # type: ignore
  File "/home/kenneth/myrenamer/venv/lib/python3.8/site-packages/werkzeug/routing.py", line 2042, in match
    raise NotFound()
werkzeug.exceptions.NotFound: 404 Not Found: The requested URL was not found on the server. If you entered the URL manually please check your spelling and try again.

During handling of the above exception, another exception occurred:

Traceback (most recent call last):
  File "/home/kenneth/myrenamer/venv/lib/python3.8/site-packages/flask/app.py", line 2073, in wsgi_app
    response = self.full_dispatch_request()
  File "/home/kenneth/myrenamer/venv/lib/python3.8/site-packages/flask/app.py", line 1518, in full_dispatch_request
    rv = self.handle_user_exception(e)
  File "/home/kenneth/myrenamer/venv/lib/python3.8/site-packages/flask/app.py", line 1386, in handle_user_exception
    return self.handle_http_exception(e)
  File "/home/kenneth/myrenamer/venv/lib/python3.8/site-packages/flask/app.py", line 1326, in handle_http_exception
    return self.ensure_sync(handler)(e)
  File "/home/kenneth/myrenamer/app/errors/handlers.py", line 7, in not_found_error
    return render_template('errors/404.html', 404)
TypeError: render_template() takes 1 positional argument but 2 were given
2022-03-19 01:22:16,609 ERROR: Exception on /favicon.ico [GET] [in /home/kenneth/myrenamer/venv/lib/python3.8/site-packages/flask/app.py:1457]
Traceback (most recent call last):
  File "/home/kenneth/myrenamer/venv/lib/python3.8/site-packages/flask/app.py", line 1516, in full_dispatch_request
    rv = self.dispatch_request()
  File "/home/kenneth/myrenamer/venv/lib/python3.8/site-packages/flask/app.py", line 1492, in dispatch_request
    self.raise_routing_exception(req)
  File "/home/kenneth/myrenamer/venv/lib/python3.8/site-packages/flask/app.py", line 1474, in raise_routing_exception
    raise request.routing_exception  # type: ignore
  File "/home/kenneth/myrenamer/venv/lib/python3.8/site-packages/flask/ctx.py", line 376, in match_request
    result = self.url_adapter.match(return_rule=True)  # type: ignore
  File "/home/kenneth/myrenamer/venv/lib/python3.8/site-packages/werkzeug/routing.py", line 2042, in match
    raise NotFound()
werkzeug.exceptions.NotFound: 404 Not Found: The requested URL was not found on the server. If you entered the URL manually please check your spelling and try again.

During handling of the above exception, another exception occurred:

Traceback (most recent call last):
  File "/home/kenneth/myrenamer/venv/lib/python3.8/site-packages/flask/app.py", line 2073, in wsgi_app
    response = self.full_dispatch_request()
  File "/home/kenneth/myrenamer/venv/lib/python3.8/site-packages/flask/app.py", line 1518, in full_dispatch_request
    rv = self.handle_user_exception(e)
  File "/home/kenneth/myrenamer/venv/lib/python3.8/site-packages/flask/app.py", line 1386, in handle_user_exception
    return self.handle_http_exception(e)
  File "/home/kenneth/myrenamer/venv/lib/python3.8/site-packages/flask/app.py", line 1326, in handle_http_exception
    return self.ensure_sync(handler)(e)
  File "/home/kenneth/myrenamer/app/errors/handlers.py", line 7, in not_found_error
    return render_template('errors/404.html', 404)
TypeError: render_template() takes 1 positional argument but 2 were given
2022-03-19 01:22:16,870 ERROR: Exception on /favicon.ico [GET] [in /home/kenneth/myrenamer/venv/lib/python3.8/site-packages/flask/app.py:1457]
Traceback (most recent call last):
  File "/home/kenneth/myrenamer/venv/lib/python3.8/site-packages/flask/app.py", line 1516, in full_dispatch_request
    rv = self.dispatch_request()
  File "/home/kenneth/myrenamer/venv/lib/python3.8/site-packages/flask/app.py", line 1492, in dispatch_request
    self.raise_routing_exception(req)
  File "/home/kenneth/myrenamer/venv/lib/python3.8/site-packages/flask/app.py", line 1474, in raise_routing_exception
    raise request.routing_exception  # type: ignore
  File "/home/kenneth/myrenamer/venv/lib/python3.8/site-packages/flask/ctx.py", line 376, in match_request
    result = self.url_adapter.match(return_rule=True)  # type: ignore
  File "/home/kenneth/myrenamer/venv/lib/python3.8/site-packages/werkzeug/routing.py", line 2042, in match
    raise NotFound()
werkzeug.exceptions.NotFound: 404 Not Found: The requested URL was not found on the server. If you entered the URL manually please check your spelling and try again.

During handling of the above exception, another exception occurred:

Traceback (most recent call last):
  File "/home/kenneth/myrenamer/venv/lib/python3.8/site-packages/flask/app.py", line 2073, in wsgi_app
    response = self.full_dispatch_request()
  File "/home/kenneth/myrenamer/venv/lib/python3.8/site-packages/flask/app.py", line 1518, in full_dispatch_request
    rv = self.handle_user_exception(e)
  File "/home/kenneth/myrenamer/venv/lib/python3.8/site-packages/flask/app.py", line 1386, in handle_user_exception
    return self.handle_http_exception(e)
  File "/home/kenneth/myrenamer/venv/lib/python3.8/site-packages/flask/app.py", line 1326, in handle_http_exception
    return self.ensure_sync(handler)(e)
  File "/home/kenneth/myrenamer/app/errors/handlers.py", line 7, in not_found_error
    return render_template('errors/404.html', 404)
TypeError: render_template() takes 1 positional argument but 2 were given
